Workbook

Sheet Summary
A1: GradNavi Sprint 1 Test Dashboard
A3: Metric | B3: Value | D3: Area | E3: Total | F3: Passed
A4: Total Test Cases | B4: =COUNTA('Test Cases'!A2:A62) | D4: Authentication | E4: =COUNTIF('Test Cases'!B$2:B$62,D4) | F4: =COUNTIFS('Test Cases'!B$2:B$62,D4,'Test Cases'!J$2:J$62,"Pass")
A5: Pass | B5: =COUNTIF('Test Cases'!J2:J62,"Pass") | D5: JWT | E5: =COUNTIF('Test Cases'!B$2:B$62,D5) | F5: =COUNTIFS('Test Cases'!B$2:B$62,D5,'Test Cases'!J$2:J$62,"Pass")
A6: Fail | B6: =COUNTIF('Test Cases'!J2:J62,"Fail") | D6: Current User | E6: =COUNTIF('Test Cases'!B$2:B$62,D6) | F6: =COUNTIFS('Test Cases'!B$2:B$62,D6,'Test Cases'!J$2:J$62,"Pass")
A7: Blocked | B7: =COUNTIF('Test Cases'!J2:J62,"Blocked") | D7: Student Profile | E7: =COUNTIF('Test Cases'!B$2:B$62,D7) | F7: =COUNTIFS('Test Cases'!B$2:B$62,D7,'Test Cases'!J$2:J$62,"Pass")
A8: Not Run | B8: =COUNTIF('Test Cases'!J2:J62,"Not Run") | D8: Ownership | E8: =COUNTIF('Test Cases'!B$2:B$62,D8) | F8: =COUNTIFS('Test Cases'!B$2:B$62,D8,'Test Cases'!J$2:J$62,"Pass")
D9: Skills | E9: =COUNTIF('Test Cases'!B$2:B$62,D9) | F9: =COUNTIFS('Test Cases'!B$2:B$62,D9,'Test Cases'!J$2:J$62,"Pass")
D10: Interests | E10: =COUNTIF('Test Cases'!B$2:B$62,D10) | F10: =COUNTIFS('Test Cases'!B$2:B$62,D10,'Test Cases'!J$2:J$62,"Pass")
A11: Sprint 1 Exit Checks | B11: Status | D11: Education | E11: =COUNTIF('Test Cases'!B$2:B$62,D11) | F11: =COUNTIFS('Test Cases'!B$2:B$62,D11,'Test Cases'!J$2:J$62,"Pass")
A12: Critical tests | B12: =IF(COUNTIFS('Test Cases'!D2:D62,"Critical",'Test Cases'!J2:J62,"Fail")+COUNTIFS('Test Cases'!D2:D62,"Critical",'Test Cases'!J2:J62,"Blocked")>0,"NOT READY",IF(COUNTIFS('Test Cases'!D2:D62,"Critical",'Test Cases'!J2:J62,"Not Run")>0,"PENDING","READY")) | D12: Experience | E12: =COUNTIF('Test Cases'!B$2:B$62,D12) | F12: =COUNTIFS('Test Cases'!B$2:B$62,D12,'Test Cases'!J$2:J$62,"Pass")
A13: Integration tests | B13: =IF(COUNTIFS('Test Cases'!C2:C62,"Integration",'Test Cases'!J2:J62,"Fail")+COUNTIFS('Test Cases'!C2:C62,"Integration",'Test Cases'!J2:J62,"Blocked")>0,"NOT READY",IF(COUNTIFS('Test Cases'!C2:C62,"Integration",'Test Cases'!J2:J62,"Not Run")>0,"PENDING","READY")) | D13: Projects | E13: =COUNTIF('Test Cases'!B$2:B$62,D13) | F13: =COUNTIFS('Test Cases'!B$2:B$62,D13,'Test Cases'!J$2:J$62,"Pass")
D14: Career Goals | E14: =COUNTIF('Test Cases'!B$2:B$62,D14) | F14: =COUNTIFS('Test Cases'!B$2:B$62,D14,'Test Cases'!J$2:J$62,"Pass")
D15: Personality | E15: =COUNTIF('Test Cases'!B$2:B$62,D15) | F15: =COUNTIFS('Test Cases'!B$2:B$62,D15,'Test Cases'!J$2:J$62,"Pass")
D16: Frontend Auth | E16: =COUNTIF('Test Cases'!B$2:B$62,D16) | F16: =COUNTIFS('Test Cases'!B$2:B$62,D16,'Test Cases'!J$2:J$62,"Pass")
D17: Frontend Profile | E17: =COUNTIF('Test Cases'!B$2:B$62,D17) | F17: =COUNTIFS('Test Cases'!B$2:B$62,D17,'Test Cases'!J$2:J$62,"Pass")
D18: Database | E18: =COUNTIF('Test Cases'!B$2:B$62,D18) | F18: =COUNTIFS('Test Cases'!B$2:B$62,D18,'Test Cases'!J$2:J$62,"Pass")
D19: Security | E19: =COUNTIF('Test Cases'!B$2:B$62,D19) | F19: =COUNTIFS('Test Cases'!B$2:B$62,D19,'Test Cases'!J$2:J$62,"Pass") | H19: Test Owner | I19: Assigned | J19: Passed
D20: Regression | E20: =COUNTIF('Test Cases'!B$2:B$62,D20) | F20: =COUNTIFS('Test Cases'!B$2:B$62,D20,'Test Cases'!J$2:J$62,"Pass") | H20: MD | I20: =COUNTIF('Test Cases'!P$2:P$62,H20) | J20: =COUNTIFS('Test Cases'!P$2:P$62,H20,'Test Cases'!J$2:J$62,"Pass")
H21: Joyee | I21: =COUNTIF('Test Cases'!P$2:P$62,H21) | J21: =COUNTIFS('Test Cases'!P$2:P$62,H21,'Test Cases'!J$2:J$62,"Pass")
H22: Jerald | I22: =COUNTIF('Test Cases'!P$2:P$62,H22) | J22: =COUNTIFS('Test Cases'!P$2:P$62,H22,'Test Cases'!J$2:J$62,"Pass")
H23: Shared | I23: =COUNTIF('Test Cases'!P$2:P$62,H23) | J23: =COUNTIFS('Test Cases'!P$2:P$62,H23,'Test Cases'!J$2:J$62,"Pass")

Sheet Test Cases
A1: Test ID | B1: Area | C1: Test Type | D1: Priority | E1: Scenario | F1: Preconditions | G1: Test Steps | H1: Expected Result | I1: Actual Result | J1: Status | K1: Tester | L1: Test Date | M1: Evidence ID | N1: Defect Reference | O1: Notes | P1: Test Owner
A2: AUTH-REG-01 | B2: Authentication | C2: API | D2: Critical | E2: Valid student registration | F2: Unique test email | G2: POST valid payload to /api/v1/auth/register/ | H2: 201 Created; Student account and StudentProfile created; response excludes password fields. | I2: 201 Created; student account created successfully. Response returned id, email, first_name, last_name, and role, with no password fields exposed. | J2: Pass | K2: MD | L2: 46282 | M2: EV-048 | O2: Valid student registration verified via Postman on feature/sprint-3. | P2: MD
A3: AUTH-REG-02 | B3: Authentication | C3: API | D3: High | E3: Missing required registration field | F3: Registration endpoint available | G3: POST payload missing one required field | H3: 400 Bad Request; required-field validation returned; account not created. | I3: 400 Bad Request returned. Required-field validation correctly identified the missing last_name field and rejected the registration request. | J3: Pass | K3: MD | L3: 46282 | M3: EV-049 | O3: Missing required registration field validation verified via Postman on feature/sprint-3. | P3: MD
A4: AUTH-REG-03 | B4: Authentication | C4: API | D4: High | E4: Duplicate email registration | F4: Existing account uses test email | G4: POST registration with existing email | H4: 409 Conflict; duplicate account not created. | I4: 409 Conflict returned. Registration using an existing email was rejected with "A user with this email already exists." Duplicate account was not created. | J4: Pass | K4: MD | L4: 46283 | M4: EV-050 | O4: Duplicate email registration validation verified via Postman on feature/sprint-3. | P4: MD
A5: AUTH-REG-04 | B5: Authentication | C5: Security | D5: Critical | E5: Registration response protects password | F5: Registration endpoint available | G5: Register account and inspect response | H5: 201 Created response excludes password, password_confirm, hashes, reset credentials, and secrets. | I5: 201 Created; registration response returned only id, email, first_name, last_name, and role. Password, password_confirm, hashes, reset credentials, tokens, and other secrets were not exposed. | J5: Pass | K5: MD | L5: 46283 | M5: EV-051 | O5: Registration response security verified via Postman on feature/sprint-3; sensitive authentication fields were not returned. | P5: MD
A6: AUTH-LOGIN-01 | B6: Authentication | C6: API | D6: Critical | E6: Valid login | F6: Active Student account exists | G6: POST valid credentials to /api/v1/auth/login/ | H6: 200 OK; access token, refresh token, and authenticated user summary returned. | I6: 200 OK; valid credentials returned access token, refresh token, and authenticated user summary containing id, email, first_name, last_name, and role. | J6: Pass | K6: MD | L6: 46283 | M6: EV-052 | O6: Valid student login verified via Postman on feature/sprint-3. | P6: MD
A7: AUTH-LOGIN-02 | B7: Authentication | C7: API | D7: Critical | E7: Invalid password | F7: Active Student account exists | G7: POST correct email with wrong password | H7: 401 Unauthorized; controlled invalid-credentials error; no tokens returned. | I7: 401 Unauthorized; incorrect password returned a controlled invalid_credentials error and no access or refresh tokens were returned. | J7: Pass | K7: MD | L7: 46283 | M7: EV-053 | O7: Invalid-password login handling verified via Postman on feature/sprint-3. | P7: MD
A8: AUTH-LOGIN-03 | B8: Authentication | C8: API | D8: High | E8: Missing login credentials | F8: Login endpoint available | G8: POST request with missing email or password | H8: 400 Bad Request; required-field validation returned in the standard error structure. | I8: 400 Bad Request; missing password returned the standard validation_error structure with password identified as a required field. | J8: Pass | K8: MD | L8: 46283 | M8: EV-054 | O8: Missing login credential validation verified via Postman on feature/sprint-3. | P8: MD
A9: AUTH-ME-01 | B9: Current User | C9: API | D9: Critical | E9: Retrieve current authenticated user | F9: Valid access token | G9: GET /api/v1/auth/me/ with Bearer token | H9: 200 OK; authenticated user's id, email, first_name, last_name, and role returned. | I9: 200 OK; authenticated request with a valid Bearer access token returned the current user's id, email, first_name, last_name, and role. | J9: Pass | K9: MD | L9: 46283 | M9: EV-055 | O9: Current authenticated user retrieval verified via Postman on feature/sprint-3 using a valid access token. | P9: MD
A10: AUTH-ME-02 | B10: Current User | C10: Security | D10: Critical | E10: Current user without token | F10: None | G10: GET /api/v1/auth/me/ without Authorization | H10: 401 Unauthorized; no account data returned | I10: 401 Unauthorized; request without Authorization returned a not_authenticated error and no account data was returned. | J10: Pass | K10: MD | L10: 46283 | M10: EV-056 | O10: Unauthenticated access to the current-user endpoint was correctly rejected via Postman on feature/sprint-3. | P10: MD
A11: JWT-REF-01 | B11: JWT | C11: API | D11: Critical | E11: Refresh valid access token | F11: Valid refresh token | G11: POST refresh token to /api/v1/auth/token/refresh/ | H11: 200 OK; valid refresh token returns a new access token. | I11: 200 OK; valid refresh token was accepted and a new access token was returned. A rotated refresh token was also issued. | J11: Pass | K11: MD | L11: 46283 | M11: EV-057 | O11: Valid JWT refresh flow verified via Postman on feature/sprint-3; refresh-token rotation was observed. | P11: MD
A12: JWT-REF-02 | B12: JWT | C12: Security | D12: Critical | E12: Reject invalid refresh token | F12: Invalid refresh token | G12: POST invalid refresh token | H12: 401 Unauthorized; invalid refresh token rejected; no access token issued. | I12: 401 Unauthorized; invalid refresh token was rejected with token_not_valid error and no access token was issued. | J12: Pass | K12: MD | L12: 46283 | M12: EV-058 | O12: Invalid JWT refresh token rejection verified via Postman on feature/sprint-3. | P12: MD
A13: JWT-REF-03 | B13: JWT | C13: Security | D13: High | E13: Reject blacklisted refresh token | F13: Blacklisting implemented; token logged out | G13: Reuse blacklisted refresh token | H13: 401 Unauthorized; blacklisted refresh token rejected; no access token issued. | I13: 401 Unauthorized; previously invalidated refresh token was rejected with token_not_valid error and no access token was issued. | J13: Pass | K13: MD | L13: 46283 | M13: EV-059 | O13: Reuse of the previously invalidated refresh token was rejected via Postman on feature/sprint-3. | P13: MD
... A16: AUTH-PWR-02 | B16: Authentication | C16: Security | D16: High | E16: Invalid password reset confirmation | F16: Invalid or expired reset credential | G16: POST reset confirmation with invalid credential | H16: 401 Unauthorized for invalid or expired reset credentials; password remains unchanged. | I16: 401 Unauthorized returned for invalid reset credentials with invalid_reset_token error. Subsequent login using the original password succeeded with 200 OK, confirming the password remained unchanged. | J16: Pass | K16: MD | L16: 46286 | M16: EV-064, EV-065 | O16: Invalid password-reset confirmation and unchanged-password behavior verified via Postman on feature/sprint-3. | P16: MD
A17: PROF-GET-01 | B17: Student Profile | C17: API | D17: Critical | E17: Authenticated student retrieves own profile | F17: Student A has profile and valid token | G17: GET /api/v1/profile/ as Student A | H17: 200 OK; only Student A profile data returned | I17: Authenticated WBS 4.8 test student opened /profile. GET /api/v1/profile/ returned HTTP 200 and the student's profile loaded in React. | J17: Pass | K17: Jerald | L17: 2026-08-28 | M17: EV-027; EV-028 | O17: Own-profile retrieval verified. Cross-student isolation is covered by OWN-01 to OWN-04. | P17: MD
A18: PROF-GET-02 | B18: Student Profile | C18: Security | D18: Critical | E18: Profile request without authentication | F18: None | G18: GET /api/v1/profile/ without token | H18: 401 Unauthorized; no profile data returned | I18: 401 Unauthorized; unauthenticated profile request returned a not_authenticated error and no profile data was returned. | J18: Pass | K18: MD | L18: 46286 | M18: EV-066 | O18: Unauthenticated access to the Student Profile endpoint was correctly rejected via Postman on feature/sprint-3. | P18: MD
A19: PROF-GET-03 | B19: Student Profile | C19: API | D19: High | E19: Profile response contains approved collections | F19: Profile has related data | G19: GET /api/v1/profile/ | H19: 200 OK; response contains skills, interests, education, experience, projects, career_goals, and personality_responses. | I19: GET /api/v1/profile/ returned HTTP 200 and persisted profile sections were displayed through the Student Profile UI across the reload, edit, and deletion checks. | J19: Pass | K19: Jerald | L19: 2026-08-28 | M19: EV-028; EV-029; EV-030 | O19: UI evidence confirms all seven profile collections are returned and rendered. Raw JSON schema was not separately captured. | P19: MD
A20: PROF-PAT-01 | B20: Student Profile | C20: API | D20: Critical | E20: Valid partial profile update | F20: Authenticated Student A | G20: PATCH approved fields | H20: 200 OK; submitted profile collections updated; omitted collections preserved. | I20: An existing Education record was edited, Save Profile submitted PATCH successfully, the updated description persisted, and unrelated profile sections remained present after refresh. | J20: Pass | K20: Jerald | L20: 2026-08-28 | M20: EV-029 | O20: Valid authenticated profile update verified through the integrated React and Django flow. | P20: MD
A21: PROF-PAT-02 | B21: Student Profile | C21: API | D21: High | E21: Invalid profile field value | F21: Authenticated Student A | G21: PATCH invalid profile data | H21: 400 Bad Request; invalid data not persisted | I21: 400 Bad Request returned for an invalid profile field value. The API returned a validation_error stating that "INVALID_LEVEL" is not a valid proficiency_level choice. A subsequent GET returned 200 OK with skills remaining empty, confirming the invalid data was not persisted. | J21: Pass | K21: MD | L21: 46286 | M21: EV-067,EV-068 | O21: Invalid Student Profile field validation and non-persistence verified via Postman on feature/sprint-3. | P21: MD
A22: PROF-PAT-03 | B22: Student Profile | C22: API | D22: Medium | E22: Empty partial request | F22: Authenticated Student A | G22: PATCH empty body | H22: 200 OK; empty PATCH leaves all profile collections unchanged. | I22: 200 OK; empty PATCH request was accepted and all Student Profile collections remained unchanged. | J22: Pass | K22: MD | L22: 46286 | M22: EV-069 | O22: Empty Student Profile PATCH behavior verified via Postman on feature/sprint-3; no profile collections were modified. | P22: MD
A23: PROF-PAT-04 | B23: Student Profile | C23: Security | D23: Critical | E23: Attempt ownership-field change | F23: Authenticated Student A | G23: PATCH another user_id or student_profile_id | H23: 400 Bad Request; user_id or student_profile_id is rejected as unsupported; ownership remains unchanged. | I23: 400 Bad Request; attempted user_id ownership-field change was rejected with validation_error stating "This field is not allowed." The unsupported ownership field was not accepted. | J23: Pass | K23: MD | L23: 46286 | M23: EV-070 | O23: Student Profile ownership-field protection verified via Postman on feature/sprint-3; client-supplied user_id was rejected as unsupported. | P23: MD
A24: PROF-PAT-05 | B24: Student Profile | C24: Database | D24: High | E24: Profile update persists | F24: Authenticated Student A | G24: PATCH valid update then GET profile | H24: 200 OK on update; a subsequent GET returns the persisted value from PostgreSQL. | I24: Profile changes persisted after successful PATCH requests and browser refreshes. Edited Education remained updated and the removed Project did not return. | J24: Pass | K24: Jerald | L24: 2026-08-28 | M24: EV-026; EV-028; EV-029; EV-030 | O24: Save-and-reload persistence verified. DB-03 separately confirms related records in PostgreSQL. | P24: Jerald
A25: OWN-01 | B25: Ownership | C25: Permission | D25: Critical | E25: Student A reads own profile | F25: Student A and B exist | G25: GET own profile as Student A | H25: 200 OK; Student A receives only Student A's authenticated profile. | I25: Authenticated as Student A. GET /api/v1/profile/ returned HTTP 200 and successfully returned Student A's authenticated profile. | J25: Pass | K25: Jerald | L25: 2026-08-28 | M25: EV-031 | O25: WBS 4.9 ownership verification. | P25: Jerald
A26: OWN-02 | B26: Ownership | C26: Permission | D26: Critical | E26: Student B reads own profile | F26: Student A and B exist | G26: GET own profile as Student B | H26: 200 OK; Student B receives only Student B's authenticated profile. | I26: Authenticated as Student B. GET /api/v1/profile/ returned HTTP 200 and successfully returned Student B's authenticated profile. | J26: Pass | K26: Jerald | L26: 2026-08-28 | M26: EV-032 | O26: WBS 4.9 ownership verification. | P26: Jerald
A27: OWN-03 | B27: Ownership | C27: Permission | D27: Critical | E27: Cross-student access blocked | F27: Student A and B exist | G27: Attempt Student B data while authenticated as A | H27: 200 OK; a client-supplied user_id does not switch profiles, and Student A still receives Student A's profile. | I27: Authenticated as Student A and attempted GET /api/v1/profile/?user_id=7 using Student B's identifier. The API returned HTTP 200 but ignored the client-supplied target identifier. The returned profile matched Student A's normal authenticated profile, confirming that Student B's protected profile could not be selected. | J27: Pass | K27: Jerald | L27: 2026-08-28 | M27: EV-033 | O27: WBS 4.9 cross-student isolation verification. | P27: Jerald
A28: OWN-04 | B28: Ownership | C28: Security | D28: Critical | E28: Cross-student ownership modification blocked | F28: Student A and B exist | G28: Authenticate as Student A and submit Student B's user ID through PATCH /api/v1/profile/. | H28: 400 Bad Request; ownership field is rejected and Student A and Student B ownership remains unchanged. | I28: Authenticated as Student A and attempted to change profile ownership by submitting Student B's user ID through PATCH /api/v1/profile/. The backend rejected the user_id field with HTTP 400. Student A remained user 6, Student B remained user 7, and both students continued retrieving their own profiles successfully. | J28: Pass | K28: Jerald | L28: 2026-08-28 | M28: EV-034 | O28: WBS 4.9 ownership-field protection verification. | P28: Jerald
A29: SKILL-01 | B29: Skills | C29: API | D29: High | E29: Add valid student skill | F29: Skill exists; feature implemented | G29: Submit valid StudentSkill relationship | H29: 200 OK; valid Skill relationship stored for the authenticated StudentProfile. | I29: Python with Proficient proficiency was added through the Student Profile UI, saved, and remained visible after browser refresh. | J29: Pass | K29: Jerald | L29: 2026-08-28 | M29: EV-028 | O29: Sprint 1 used prepared shared Skill reference records. Formal reference-data API remains under later work. | P29: Jerald
A30: SKILL-02 | B30: Skills | C30: API | D30: High | E30: Reject invalid skill reference | F30: Feature implemented | G30: Submit non-existent Skill ID | H30: 400 Bad Request with 'Skill does not exist'; invalid relationship is not stored. | I30: Authenticated as Student A and submitted nonexistent Skill ID 999999 with the valid proficiency value "foundational" through PATCH /api/v1/profile/. The backend returned HTTP 400 with a "Skill does not exist" validation error. A subsequent GET confirmed the Student Skill collection was unchanged. | J30: Pass | K30: Jerald | L30: 2026-08-28 | M30: EV-035 | O30: WBS 4.9 invalid Skill reference validation. | P30: Jerald
A31: SKILL-03 | B31: Skills | C31: Validation | D31: High | E31: Reject invalid proficiency level | F31: Scale confirmed | G31: Submit value outside approved set | H31: 400 Bad Request; invalid proficiency choice is rejected and the StudentSkill collection stays unchanged. | I31: Authenticated as Student A and submitted the valid Python Skill reference, ID 1, with the invalid proficiency value "expert" through PATCH /api/v1/profile/. The backend returned HTTP 400 and rejected the value as an invalid choice. A subsequent GET confirmed the Student Skill collection was unchanged. | J31: Pass | K31: Jerald | L31: 2026-08-28 | M31: EV-036 | O31: WBS 4.9 proficiency-choice validation. | P31: Jerald
A32: SKILL-04 | B32: Skills | C32: Validation | D32: Medium | E32: Prevent duplicate student skill | F32: Student already linked to Skill | G32: Submit duplicate relationship | H32: 400 Bad Request; duplicate Skill references are rejected and no duplicate relationship is stored. | I32: Authenticated as Student A and submitted the Python Skill reference, ID 1, twice in the same PATCH /api/v1/profile/ request. The backend returned HTTP 400 and rejected the duplicate Skill references with a "Duplicate values are not allowed" validation error. A subsequent GET confirmed the Student Skill collection was unchanged. | J32: Pass | K32: Jerald | L32: 2026-08-28 | M32: EV-037 | O32: WBS 4.9 duplicate StudentSkill validation. | P32: Jerald
A33: INT-01 | B33: Interests | C33: API | D33: High | E33: Add valid student interest | F33: Interest exists | G33: Submit valid StudentInterest relationship | H33: 200 OK; valid Interest relationship stored for the authenticated StudentProfile. | I33: Artificial Intelligence was selected from the prepared shared Interest references, saved, and remained visible after browser refresh. | J33: Pass | K33: Jerald | L33: 2026-08-28 | M33: EV-028 | O33: Interest category remained shared reference data and was not edited by the student. | P33: Jerald
A34: INT-02 | B34: Interests | C34: API | D34: High | E34: Reject invalid interest reference | F34: Feature implemented | G34: Submit non-existent Interest ID | H34: 400 Bad Request with 'Interest does not exist'; invalid relationship is not stored. | I34: Authenticated as Student A and submitted nonexistent Interest ID 999999 through PATCH /api/v1/profile/. The backend returned HTTP 400 with an "Interest does not exist" validation error. A subsequent GET confirmed the Student Interest collection was unchanged. | J34: Pass | K34: Jerald | L34: 2026-08-28 | M34: EV-038 | O34: WBS 4.9 invalid Interest reference validation. | P34: Jerald
A35: INT-03 | B35: Interests | C35: Permission | D35: High | E35: Protect shared Interest data | F35: Student profile API available | G35: Attempt shared Interest edit via student profile | H35: 400 Bad Request when shared Interest metadata is supplied; shared reference data and StudentInterest relationships stay unchanged. | I35: Authenticated as Student A and attempted to modify the shared Artificial Intelligence Interest, ID 1, by submitting a category field through PATCH /api/v1/profile/. The backend returned HTTP 400 and rejected category as an unsupported field. Direct database verification confirmed the shared Interest category remained "Technology". A subsequent profile GET confirmed Student A's Interest relationships were unchanged. | J35: Pass | K35: Jerald | L35: 2026-08-28 | M35: EV-039 | O35: WBS 4.9 shared Interest protection verification. | P35: Jerald
... A46: FE-AUTH-03 | B46: Frontend Auth | C46: Integration | D46: High | E46: Frontend invalid login error | F46: React login available | G46: Use invalid credentials | H46: Controlled login error is shown; no authenticated state or tokens are stored. | I46: Wrong password and nonexistent-user attempts returned 401 with the same controlled credentials error. Missing fields were rejected by frontend validation. | J46: Pass | K46: Jerald | L46: 2026-08-22 | M46: EV-008; EV-009; EV-010 | O46: Invalid-login behaviour verified through the React UI. | P46: Joyee
A47: FE-AUTH-04 | B47: Frontend Auth | C47: Integration | D47: High | E47: Frontend token refresh behaviour | F47: JWT frontend strategy implemented | G47: Trigger expired access token flow | H47: Expired access-token flow follows the implemented refresh strategy; successful refresh restores the authenticated request. | I47: Automatic token refresh was manually verified earlier, but a dedicated screenshot is not included in this evidence package. | J47: Pass | K47: Jerald | L47: 2026-08-22 | O47: Manual refresh flow was observed. No dedicated screenshot is packaged for this case. | P47: Joyee
A48: FE-AUTH-05 | B48: Frontend Auth | C48: Integration | D48: High | E48: Frontend logout flow | F48: Authenticated frontend session | G48: Use logout action | H48: Logout clears local authentication state and protected routes require authentication. | I48: Logout returned the frontend to /login and cleared GradNavi access token, refresh token, and stored-user entries from localStorage. | J48: Pass | K48: Jerald | L48: 2026-08-22 | M48: EV-014 | O48: Frontend logout behaviour verified. | P48: Joyee
A49: FE-PROF-01 | B49: Frontend Profile | C49: Integration | D49: Critical | E49: Load profile in UI | F49: Authenticated frontend and profile API | G49: Open Student Profile page | H49: Authenticated profile GET succeeds and saved Student data is displayed. | I49: Authenticated Student Profile page loaded successfully. GET /api/v1/profile/ returned HTTP 200 and saved Student Profile data displayed after refresh. | J49: Pass | K49: Jerald | L49: 2026-08-28 | M49: EV-028 | O49: Frontend GET integration verified. | P49: Joyee
A50: FE-PROF-02 | B50: Frontend Profile | C50: Integration | D50: Critical | E50: Update profile in UI | F50: Authenticated frontend and update API | G50: Edit valid profile data and save | H50: Valid profile PATCH succeeds; the UI shows success and saved changes persist. | I50: Student added, edited and removed profile data, then used the single Save Profile action. PATCH /api/v1/profile/ returned HTTP 200 and the UI displayed a successful save state. | J50: Pass | K50: Jerald | L50: 2026-08-28 | M50: EV-026; EV-027; EV-029; EV-030 | O50: Frontend PATCH integration verified across add, edit and remove flows. | P50: Joyee
A51: FE-PROF-03 | B51: Frontend Profile | C51: Integration | D51: High | E51: Display profile validation error | F51: Authenticated frontend | G51: Submit invalid profile data | H51: Frontend shows validation feedback, does not add invalid data, and does not send a profile PATCH request. | I51: Submitted an Education record through the Student Profile UI with start date 2026-06-01 and end date 2025-06-01. The frontend displayed "End date must not be earlier than start date." The invalid Education record was not added to the profile, and no new profile PATCH request was sent for the invalid form data. | J51: Pass | K51: Jerald | L51: 2026-08-29 | M51: EV-045 | O51: WBS 4.9 frontend validation verification. No profile PATCH request was sent for the invalid form data. | P51: Joyee
A52: FE-PROF-04 | B52: Frontend Profile | C52: Integration | D52: High | E52: Profile remains after reload | F52: Successful profile update | G52: Reload or refetch profile | H52: Reload or refetch displays the previously saved profile data. | I52: Saved profile information remained after browser refresh. Edited Education remained updated and the removed Project did not return. | J52: Pass | K52: Jerald | L52: 2026-08-28 | M52: EV-028; EV-029; EV-030 | O52: Reload persistence verified. | P52: Joyee
...

Sheet Evidence Index
A1: Evidence ID | B1: Test ID | C1: Evidence Type | D1: Description | E1: Location / Link | F1: Captured By | G1: Date | H1: Notes
A2: EV-001 | B2: FE-AUTH-01 | C2: Screenshot | D2: Registration success HTTP status | E2: docs/testing/evidence/sprint-1/EV-001-auth-registration-success-status.png | F2: Jerald | G2: 2026-08-22 | H2: Frontend authentication evidence
A3: EV-002 | B3: FE-AUTH-01 | C3: Screenshot | D3: Registration success response excludes password fields | E3: docs/testing/evidence/sprint-1/EV-002-auth-registration-success-response.png | F3: Jerald | G3: 2026-08-22 | H3: Frontend authentication evidence
A4: EV-003 | B4: FE-AUTH-01 | C4: Screenshot | D4: Registration validation feedback | E4: docs/testing/evidence/sprint-1/EV-003-auth-registration-validation.png | F4: Jerald | G4: 2026-08-22 | H4: Frontend authentication evidence
A5: EV-004 | B5: FE-AUTH-01 | C5: Screenshot | D5: Registration validation API response | E5: docs/testing/evidence/sprint-1/EV-004-auth-registration-validation-response.png | F5: Jerald | G5: 2026-08-22 | H5: Frontend authentication evidence
A6: EV-005 | B6: FE-AUTH-01 | C6: Screenshot | D6: Registration password mismatch validation | E6: docs/testing/evidence/sprint-1/EV-005-auth-registration-password-mismatch.png | F6: Jerald | G6: 2026-08-22 | H6: Frontend authentication evidence
A7: EV-006 | B7: FE-AUTH-01 | C7: Screenshot | D7: Duplicate registration handling | E7: docs/testing/evidence/sprint-1/EV-006-auth-registration-duplicate.png | F7: Jerald | G7: 2026-08-22 | H7: Frontend authentication evidence
A8: EV-007 | B8: FE-AUTH-02 | C8: Screenshot | D8: Successful frontend login | E8: docs/testing/evidence/sprint-1/EV-007-auth-login-success.png | F8: Jerald | G8: 2026-08-22 | H8: Frontend authentication evidence
A9: EV-008 | B9: FE-AUTH-03 | C9: Screenshot | D9: Invalid password login handling | E9: docs/testing/evidence/sprint-1/EV-008-auth-login-invalid-password.png | F9: Jerald | G9: 2026-08-22 | H9: Frontend authentication evidence
A10: EV-009 | B10: FE-AUTH-03 | C10: Screenshot | D10: Nonexistent-user login handling | E10: docs/testing/evidence/sprint-1/EV-009-auth-login-nonexistent-user.png | F10: Jerald | G10: 2026-08-22 | H10: Frontend authentication evidence
A11: EV-010 | B11: FE-AUTH-03 | C11: Screenshot | D11: Required login field validation | E11: docs/testing/evidence/sprint-1/EV-010-auth-login-required-fields.png | F11: Jerald | G11: 2026-08-22 | H11: Frontend authentication evidence
A12: EV-011 | B12: FE-AUTH-02 | C12: Screenshot | D12: Protected-route redirect before authentication | E12: docs/testing/evidence/sprint-1/EV-011-auth-protected-route-redirect.png | F12: Jerald | G12: 2026-08-22 | H12: Frontend authentication evidence
... A48: EV-047 | B48: REG-02 | C48: Screenshot | D48: Student Profile regression checks for GET, PATCH, ownership, and validation | E48: docs/testing/evidence/sprint-1/EV-047-reg-02-student-profile-regression.png | F48: Jerald | G48: 2026-08-29 | H48: WBS 4.9 regression evidence
A49: EV-048 | B49: AUTH-REG-01 | C49: Screenshot | D49: Valid student registration | E49: docs/testing/evidence/sprint-1/EV-048.png | F49: MD | G49: 46282
A50: EV-049 | B50: AUTH-REG-02 | C50: Screenshot | D50: Missing required registration field | E50: docs/testing/evidence/sprint-1/EV-049.png | F50: MD | G50: 46282
A51: EV-050 | B51: AUTH-REG-03 | C51: Screenshot | D51: Duplicate email registration | E51: docs/testing/evidence/sprint-1/EV-050.png | F51: MD | G51: 46283
A52: EV-051 | B52: AUTH-REG-04 | C52: Screenshot | D52: Registration response protects password | E52: docs/testing/evidence/sprint-1/EV-051.png | F52: MD | G52: 46283
A53: EV-052 | B53: AUTH-LOGIN-01 | C53: Screenshot | D53: Valid login | E53: docs/testing/evidence/sprint-1/EV-052.png | F53: MD | G53: 46283
A54: EV-053 | B54: AUTH-LOGIN-02 | C54: Screenshot | D54: Invalid password | E54: docs/testing/evidence/sprint-1/EV-053.png | F54: MD | G54: 46283
A55: EV-054 | B55: AUTH-LOGIN-03 | C55: Screenshot | D55: Missing login credentials | E55: docs/testing/evidence/sprint-1/EV-054.png | F55: MD | G55: 46283
A56: EV-055 | B56: AUTH-ME-01 | C56: Screenshot | D56: Retrieve current authenticated user | E56: docs/testing/evidence/sprint-1/EV-055.png | F56: MD | G56: 46283
A57: EV-056 | B57: AUTH-ME-02 | C57: Screenshot | D57: Current user without token | E57: docs/testing/evidence/sprint-1/EV-056.png | F57: MD | G57: 46283
A58: EV-057 | B58: JWT-REF-01 | C58: Screenshot | D58: Refresh valid access token | E58: docs/testing/evidence/sprint-1/EV-057.png | F58: MD | G58: 46283
A59: EV-058 | B59: JWT-REF-02 | C59: Screenshot | D59: Reject invalid refresh token | E59: docs/testing/evidence/sprint-1/EV-058.png | F59: MD | G59: 46283
A60: EV-059 | B60: JWT-REF-03 | C60: Screenshot | D60: Reject blacklisted refresh token | E60: docs/testing/evidence/sprint-1/EV-059.png | F60: MD | G60: 46283
... A71: EV-070 | B71: PROF-PAT-04 | C71: Screenshot | D71: Attempt ownership-field change | E71: docs/testing/evidence/sprint-1/EV-070.png | F71: MD | G71: 46286

Sheet Reference
A1: Status | B1: Test Type | C1: Priority | D1: Area | F1: Reference | G1: Location | I1: Test Owner | J1: Responsibility
A2: Not Run | B2: Unit | C2: Critical | D2: Authentication | F2: Sprint 1 Test Plan | G2: docs/testing/sprint-1-test-plan.md | I2: MD | J2: Authentication implementation tests plus core Student Profile API behaviour
A3: Pass | B3: API | C3: High | D3: JWT | F3: Sprint 1 Integration Plan | G3: docs/system-design/sprint-1-integration-plan.md | I3: Joyee | J3: Frontend authentication/Profile tests and frontend secret exposure check
A4: Fail | B4: Permission | C4: Medium | D4: Current User | F4: REST API Design | G4: docs/system-design/rest-api-design.md | I4: Jerald | J4: Backend Profile verification, ownership, related profile data, database, CORS, and integration support
A5: Blocked | B5: Integration | C5: Low | D5: Student Profile | F5: Security Architecture | G5: docs/system-design/security-architecture.md | I5: Shared | J5: Cross-team security, persistence, and regression checks
B6: Manual | D6: Ownership | F6: Student Profile Data Design | G6: docs/system-design/student-profile-data-design.md
B7: Regression | D7: Skills | F7: Auth API Testing | G7: backend/docs/AUTH_API_TESTING.md
B8: Security | D8: Interests
B9: Database | D9: Education | F9: Field Guidance | G9: Meaning
B10: Validation | D10: Experience | F10: Test Owner | G10: Person responsible for ensuring the test is completed
D11: Projects | F11: Tester | G11: Person who actually executes the test and records the result
D12: Career Goals
D13: Personality
D14: Frontend Auth
D15: Frontend Profile
D16: Database
D17: Security
D18: Regression
